Workbook

Sheet Dashboard
B1: ¿CÓMO VAMOS CON LA PLANEACIÓN?
B2: Tablero de lectura fácil · CENTEC Córdoba · Los números salen solos de la hoja «Registro»
B4: Año que quiere ver: | E4: 2027 | G4: Período (escriba 0 para todo el año): | K4: 0 | L4: ← cambie solo las casillas amarillas
B6: NOTA DEL COLEGIO (de 0 a 100) | F6: =IF(NOT(ISNUMBER(Tablero!B6)),"Todavía no hay datos suficientes para este año. Registre evidencias en la hoja Registro.",IF(Tablero!B6>=85,"VERDE. El colegio cumple muy bien lo que planeó. Hay que mantenerlo y compartir lo que funciona.",IF(Tablero!B6>=70,"AMARILLO. El colegio cumple, pero le falta. Revise abajo qué es lo que más hay que mejorar.","ROJO. Lo planeado no se está cumpliendo. Se necesita un plan de mejora inmediato."))) -> AMARILLO. El colegio cumple, pero le falta. Revise abajo qué es lo que más hay que mejorar. | P6: DATOS DE LOS GRÁFICOS (no editar)
B7: =IF(ISNUMBER(Tablero!B6),ROUND(Tablero!B6,0),"Sin datos") -> 78 | P7: Docente | Q7: Verde | R7: Amarillo | S7: Rojo | U7: Estado | V7: Docentes
P8: =IF(Tablero!A26="","",SUBSTITUTE(Tablero!A26,"EJEMPLO ","")) -> Docente A | Q8: =IF(Tablero!C26="Verde",ROUND(Tablero!B26,0),0) -> 94 | R8: =IF(Tablero!C26="Amarillo",ROUND(Tablero!B26,0),0) -> 0 | S8: =IF(Tablero!C26="Rojo",ROUND(Tablero!B26,0),0) -> 0 | U8: Verde | V8: =B15 -> 3
P9: =IF(Tablero!A27="","",SUBSTITUTE(Tablero!A27,"EJEMPLO ","")) -> Docente B | Q9: =IF(Tablero!C27="Verde",ROUND(Tablero!B27,0),0) -> 0 | R9: =IF(Tablero!C27="Amarillo",ROUND(Tablero!B27,0),0) -> 83 | S9: =IF(Tablero!C27="Rojo",ROUND(Tablero!B27,0),0) -> 0 | U9: Amarillo | V9: =E15 -> 3
P10: =IF(Tablero!A28="","",SUBSTITUTE(Tablero!A28,"EJEMPLO ","")) -> Docente C | Q10: =IF(Tablero!C28="Verde",ROUND(Tablero!B28,0),0) -> 0 | R10: =IF(Tablero!C28="Amarillo",ROUND(Tablero!B28,0),0) -> 0 | S10: =IF(Tablero!C28="Rojo",ROUND(Tablero!B28,0),0) -> 69 | U10: Rojo | V10: =H15 -> 2
P11: =IF(Tablero!A29="","",SUBSTITUTE(Tablero!A29,"EJEMPLO ","")) -> Docente D | Q11: =IF(Tablero!C29="Verde",ROUND(Tablero!B29,0),0) -> 91 | R11: =IF(Tablero!C29="Amarillo",ROUND(Tablero!B29,0),0) -> 0 | S11: =IF(Tablero!C29="Rojo",ROUND(Tablero!B29,0),0) -> 0 | U11: Gris | V11: =K15 -> 0
P12: =IF(Tablero!A30="","",SUBSTITUTE(Tablero!A30,"EJEMPLO ","")) -> Docente E | Q12: =IF(Tablero!C30="Verde",ROUND(Tablero!B30,0),0) -> 0 | R12: =IF(Tablero!C30="Amarillo",ROUND(Tablero!B30,0),0) -> 72 | S12: =IF(Tablero!C30="Rojo",ROUND(Tablero!B30,0),0) -> 0
B13: ¿CUÁNTOS DOCENTES ESTÁN EN CADA COLOR? | P13: =IF(Tablero!A31="","",SUBSTITUTE(Tablero!A31,"EJEMPLO ","")) -> Docente F | Q13: =IF(Tablero!C31="Verde",ROUND(Tablero!B31,0),0) -> 0 | R13: =IF(Tablero!C31="Amarillo",ROUND(Tablero!B31,0),0) -> 0 | S13: =IF(Tablero!C31="Rojo",ROUND(Tablero!B31,0),0) -> 52
B14: VERDE | E14: AMARILLO | H14: ROJO | K14: GRIS | P14: =IF(Tablero!A32="","",SUBSTITUTE(Tablero!A32,"EJEMPLO ","")) -> Docente G | Q14: =IF(Tablero!C32="Verde",ROUND(Tablero!B32,0),0) -> 86 | R14: =IF(Tablero!C32="Amarillo",ROUND(Tablero!B32,0),0) -> 0 | S14: =IF(Tablero!C32="Rojo",ROUND(Tablero!B32,0),0) -> 0 | U14: Componente | V14: Verde | W14: Amarillo | X14: Rojo | Y14: Valor
B15: =COUNTIF(Tablero!$C$26:$C$65,"Verde") -> 3 | E15: =COUNTIF(Tablero!$C$26:$C$65,"Amarillo") -> 3 | H15: =COUNTIF(Tablero!$C$26:$C$65,"Rojo") -> 2 | K15: =COUNTIFS(Tablero!$A$26:$A$65,"<>",Tablero!$B$26:$B$65,"Sin datos") -> 0 | P15: =IF(Tablero!A33="","",SUBSTITUTE(Tablero!A33,"EJEMPLO ","")) -> Docente H | Q15: =IF(Tablero!C33="Verde",ROUND(Tablero!B33,0),0) -> 0 | R15: =IF(Tablero!C33="Amarillo",ROUND(Tablero!B33,0),0) -> 73 | S15: =IF(Tablero!C33="Rojo",ROUND(Tablero!B33,0),0) -> 0 | U15: Planeó a tiempo | V15: =IF(AND(ISNUMBER(Y15),N(Y15)>=85),Y15,0) -> 0 | W15: =IF(AND(ISNUMBER(Y15),N(Y15)>=70,N(Y15)<85),Y15,0) -> 83 | X15: =IF(AND(ISNUMBER(Y15),N(Y15)<70),Y15,0) -> 0 | Y15: =IF(ISNUMBER(Tablero!B13),ROUND(Tablero!B13,0),"") -> 83
P16: =IF(Tablero!A34="","",SUBSTITUTE(Tablero!A34,"EJEMPLO ","")) | Q16: =IF(Tablero!C34="Verde",ROUND(Tablero!B34,0),0) -> 0 | R16: =IF(Tablero!C34="Amarillo",ROUND(Tablero!B34,0),0) -> 0 | S16: =IF(Tablero!C34="Rojo",ROUND(Tablero!B34,0),0) -> 0 | U16: Cumplió las semanas | V16: =IF(AND(ISNUMBER(Y16),N(Y16)>=85),Y16,0) -> 88 | W16: =IF(AND(ISNUMBER(Y16),N(Y16)>=70,N(Y16)<85),Y16,0) -> 0 | X16: =IF(AND(ISNUMBER(Y16),N(Y16)<70),Y16,0) -> 0 | Y16: =IF(ISNUMBER(Tablero!B14),ROUND(Tablero!B14,0),"") -> 88
P17: =IF(Tablero!A35="","",SUBSTITUTE(Tablero!A35,"EJEMPLO ","")) | Q17: =IF(Tablero!C35="Verde",ROUND(Tablero!B35,0),0) -> 0 | R17: =IF(Tablero!C35="Amarillo",ROUND(Tablero!B35,0),0) -> 0 | S17: =IF(Tablero!C35="Rojo",ROUND(Tablero!B35,0),0) -> 0 | U17: Enseñó los DBA | V17: =IF(AND(ISNUMBER(Y17),N(Y17)>=85),Y17,0) -> 0 | W17: =IF(AND(ISNUMBER(Y17),N(Y17)>=70,N(Y17)<85),Y17,0) -> 84 | X17: =IF(AND(ISNUMBER(Y17),N(Y17)<70),Y17,0) -> 0 | Y17: =IF(ISNUMBER(Tablero!B15),ROUND(Tablero!B15,0),"") -> 84
B18: cumplen muy bien | E18: cumplen a medias | H18: no cumplen | K18: faltan datos | P18: =IF(Tablero!A36="","",SUBSTITUTE(Tablero!A36,"EJEMPLO ","")) | Q18: =IF(Tablero!C36="Verde",ROUND(Tablero!B36,0),0) -> 0 | R18: =IF(Tablero!C36="Amarillo",ROUND(Tablero!B36,0),0) -> 0 | S18: =IF(Tablero!C36="Rojo",ROUND(Tablero!B36,0),0) -> 0 | U18: Calidad del planeador | V18: =IF(AND(ISNUMBER(Y18),N(Y18)>=85),Y18,0) -> 0 | W18: =IF(AND(ISNUMBER(Y18),N(Y18)>=70,N(Y18)<85),Y18,0) -> 73 | X18: =IF(AND(ISNUMBER(Y18),N(Y18)<70),Y18,0) -> 0 | Y18: =IF(ISNUMBER(Tablero!B16),ROUND(Tablero!B16,0),"") -> 73
B19: =IFERROR("De cada 10 docentes, "&ROUND(10*COUNTIF(Tablero!$C$26:$C$65,"Verde")/COUNTA(Tablero!$A$26:$A$65),0)&" están en verde y "&ROUND(10*COUNTIF(Tablero!$C$26:$C$65,"Rojo")/COUNTA(Tablero!$A$26:$A$65),0)&" están en rojo.","") -> De cada 10 docentes, 4 están en verde y 3 están en rojo. | P19: =IF(Tablero!A37="","",SUBSTITUTE(Tablero!A37,"EJEMPLO ","")) | Q19: =IF(Tablero!C37="Verde",ROUND(Tablero!B37,0),0) -> 0 | R19: =IF(Tablero!C37="Amarillo",ROUND(Tablero!B37,0),0) -> 0 | S19: =IF(Tablero!C37="Rojo",ROUND(Tablero!B37,0),0) -> 0 | U19: Cuadernos | V19: =IF(AND(ISNUMBER(Y19),N(Y19)>=85),Y19,0) -> 0 | W19: =IF(AND(ISNUMBER(Y19),N(Y19)>=70,N(Y19)<85),Y19,0) -> 74 | X19: =IF(AND(ISNUMBER(Y19),N(Y19)<70),Y19,0) -> 0 | Y19: =IF(ISNUMBER(Tablero!B17),ROUND(Tablero!B17,0),"") -> 74
P20: =IF(Tablero!A38="","",SUBSTITUTE(Tablero!A38,"EJEMPLO ","")) | Q20: =IF(Tablero!C38="Verde",ROUND(Tablero!B38,0),0) -> 0 | R20: =IF(Tablero!C38="Amarillo",ROUND(Tablero!B38,0),0) -> 0 | S20: =IF(Tablero!C38="Rojo",ROUND(Tablero!B38,0),0) -> 0 | U20: Clase observada | V20: =IF(AND(ISNUMBER(Y20),N(Y20)>=85),Y20,0) -> 0 | W20: =IF(AND(ISNUMBER(Y20),N(Y20)>=70,N(Y20)<85),Y20,0) -> 73 | X20: =IF(AND(ISNUMBER(Y20),N(Y20)<70),Y20,0) -> 0 | Y20: =IF(ISNUMBER(Tablero!B18),ROUND(Tablero!B18,0),"") -> 73
B21: NOTA DE CADA DOCENTE (de 0 a 100) · el color dice cómo va | P21: =IF(Tablero!A39="","",SUBSTITUTE(Tablero!A39,"EJEMPLO ","")) | Q21: =IF(Tablero!C39="Verde",ROUND(Tablero!B39,0),0) -> 0 | R21: =IF(Tablero!C39="Amarillo",ROUND(Tablero!B39,0),0) -> 0 | S21: =IF(Tablero!C39="Rojo",ROUND(Tablero!B39,0),0) -> 0 | U21: Lo que aprendieron | V21: =IF(AND(ISNUMBER(Y21),N(Y21)>=85),Y21,0) -> 0 | W21: =IF(AND(ISNUMBER(Y21),N(Y21)>=70,N(Y21)<85),Y21,0) -> 71 | X21: =IF(AND(ISNUMBER(Y21),N(Y21)<70),Y21,0) -> 0 | Y21: =IF(ISNUMBER(Tablero!B19),ROUND(Tablero!B19,0),"") -> 71
P22: =IF(Tablero!A40="","",SUBSTITUTE(Tablero!A40,"EJEMPLO ","")) | Q22: =IF(Tablero!C40="Verde",ROUND(Tablero!B40,0),0) -> 0 | R22: =IF(Tablero!C40="Amarillo",ROUND(Tablero!B40,0),0) -> 0 | S22: =IF(Tablero!C40="Rojo",ROUND(Tablero!B40,0),0) -> 0 | U22: Inclusión (PIAR) | V22: =IF(AND(ISNUMBER(Y22),N(Y22)>=85),Y22,0) -> 94 | W22: =IF(AND(ISNUMBER(Y22),N(Y22)>=70,N(Y22)<85),Y22,0) -> 0 | X22: =IF(AND(ISNUMBER(Y22),N(Y22)<70),Y22,0) -> 0 | Y22: =IF(ISNUMBER(Tablero!B20),ROUND(Tablero!B20,0),"") -> 94
P23: =IF(Tablero!A41="","",SUBSTITUTE(Tablero!A41,"EJEMPLO ","")) | Q23: =IF(Tablero!C41="Verde",ROUND(Tablero!B41,0),0) -> 0 | R23: =IF(Tablero!C41="Amarillo",ROUND(Tablero!B41,0),0) -> 0 | S23: =IF(Tablero!C41="Rojo",ROUND(Tablero!B41,0),0) -> 0 | U23: Proyectos transversales | V23: =IF(AND(ISNUMBER(Y23),N(Y23)>=85),Y23,0) -> 85 | W23: =IF(AND(ISNUMBER(Y23),N(Y23)>=70,N(Y23)<85),Y23,0) -> 0 | X23: =IF(AND(ISNUMBER(Y23),N(Y23)<70),Y23,0) -> 0 | Y23: =IF(ISNUMBER(Tablero!B21),ROUND(Tablero!B21,0),"") -> 85
P24: =IF(Tablero!A42="","",SUBSTITUTE(Tablero!A42,"EJEMPLO ","")) | Q24: =IF(Tablero!C42="Verde",ROUND(Tablero!B42,0),0) -> 0 | R24: =IF(Tablero!C42="Amarillo",ROUND(Tablero!B42,0),0) -> 0 | S24: =IF(Tablero!C42="Rojo",ROUND(Tablero!B42,0),0) -> 0 | U24: Opinión de estudiantes | V24: =IF(AND(ISNUMBER(Y24),N(Y24)>=85),Y24,0) -> 0 | W24: =IF(AND(ISNUMBER(Y24),N(Y24)>=70,N(Y24)<85),Y24,0) -> 81 | X24: =IF(AND(ISNUMBER(Y24),N(Y24)<70),Y24,0) -> 0 | Y24: =IF(ISNUMBER(Tablero!B22),ROUND(Tablero!B22,0),"") -> 81
P25: =IF(Tablero!A43="","",SUBSTITUTE(Tablero!A43,"EJEMPLO ","")) | Q25: =IF(Tablero!C43="Verde",ROUND(Tablero!B43,0),0) -> 0 | R25: =IF(Tablero!C43="Amarillo",ROUND(Tablero!B43,0),0) -> 0 | S25: =IF(Tablero!C43="Rojo",ROUND(Tablero!B43,0),0) -> 0
P26: =IF(Tablero!A44="","",SUBSTITUTE(Tablero!A44,"EJEMPLO ","")) | Q26: =IF(Tablero!C44="Verde",ROUND(Tablero!B44,0),0) -> 0 | R26: =IF(Tablero!C44="Amarillo",ROUND(Tablero!B44,0),0) -> 0 | S26: =IF(Tablero!C44="Rojo",ROUND(Tablero!B44,0),0) -> 0
P27: =IF(Tablero!A45="","",SUBSTITUTE(Tablero!A45,"EJEMPLO ","")) | Q27: =IF(Tablero!C45="Verde",ROUND(Tablero!B45,0),0) -> 0 | R27: =IF(Tablero!C45="Amarillo",ROUND(Tablero!B45,0),0) -> 0 | S27: =IF(Tablero!C45="Rojo",ROUND(Tablero!B45,0),0) -> 0 | U27: Año | V27: Nota del colegio
P28: =IF(Tablero!A46="","",SUBSTITUTE(Tablero!A46,"EJEMPLO ","")) | Q28: =IF(Tablero!C46="Verde",ROUND(Tablero!B46,0),0) -> 0 | R28: =IF(Tablero!C46="Amarillo",ROUND(Tablero!B46,0),0) -> 0 | S28: =IF(Tablero!C46="Rojo",ROUND(Tablero!B46,0),0) -> 0 | U28: ='Año vs año'!B4 -> 2027 | V28: =IF(ISNUMBER('Año vs año'!B5),ROUND('Año vs año'!B5,0),0) -> 78
P29: =IF(Tablero!A47="","",SUBSTITUTE(Tablero!A47,"EJEMPLO ","")) | Q29: =IF(Tablero!C47="Verde",ROUND(Tablero!B47,0),0) -> 0 | R29: =IF(Tablero!C47="Amarillo",ROUND(Tablero!B47,0),0) -> 0 | S29: =IF(Tablero!C47="Rojo",ROUND(Tablero!B47,0),0) -> 0 | U29: ='Año vs año'!C4 -> 2028 | V29: =IF(ISNUMBER('Año vs año'!C5),ROUND('Año vs año'!C5,0),0) -> 83
P30: =IF(Tablero!A48="","",SUBSTITUTE(Tablero!A48,"EJEMPLO ","")) | Q30: =IF(Tablero!C48="Verde",ROUND(Tablero!B48,0),0) -> 0 | R30: =IF(Tablero!C48="Amarillo",ROUND(Tablero!B48,0),0) -> 0 | S30: =IF(Tablero!C48="Rojo",ROUND(Tablero!B48,0),0) -> 0 | U30: ='Año vs año'!D4 -> 2029 | V30: =IF(ISNUMBER('Año vs año'!D5),ROUND('Año vs año'!D5,0),0) -> 0
P31: =IF(Tablero!A49="","",SUBSTITUTE(Tablero!A49,"EJEMPLO ","")) | Q31: =IF(Tablero!C49="Verde",ROUND(Tablero!B49,0),0) -> 0 | R31: =IF(Tablero!C49="Amarillo",ROUND(Tablero!B49,0),0) -> 0 | S31: =IF(Tablero!C49="Rojo",ROUND(Tablero!B49,0),0) -> 0 | U31: ='Año vs año'!E4 -> 2030 | V31: =IF(ISNUMBER('Año vs año'!E5),ROUND('Año vs año'!E5,0),0) -> 0
P32: =IF(Tablero!A50="","",SUBSTITUTE(Tablero!A50,"EJEMPLO ","")) | Q32: =IF(Tablero!C50="Verde",ROUND(Tablero!B50,0),0) -> 0 | R32: =IF(Tablero!C50="Amarillo",ROUND(Tablero!B50,0),0) -> 0 | S32: =IF(Tablero!C50="Rojo",ROUND(Tablero!B50,0),0) -> 0 | U32: ='Año vs año'!F4 -> 2031 | V32: =IF(ISNUMBER('Año vs año'!F5),ROUND('Año vs año'!F5,0),0) -> 0
P33: =IF(Tablero!A51="","",SUBSTITUTE(Tablero!A51,"EJEMPLO ","")) | Q33: =IF(Tablero!C51="Verde",ROUND(Tablero!B51,0),0) -> 0 | R33: =IF(Tablero!C51="Amarillo",ROUND(Tablero!B51,0),0) -> 0 | S33: =IF(Tablero!C51="Rojo",ROUND(Tablero!B51,0),0) -> 0
P34: =IF(Tablero!A52="","",SUBSTITUTE(Tablero!A52,"EJEMPLO ","")) | Q34: =IF(Tablero!C52="Verde",ROUND(Tablero!B52,0),0) -> 0 | R34: =IF(Tablero!C52="Amarillo",ROUND(Tablero!B52,0),0) -> 0 | S34: =IF(Tablero!C52="Rojo",ROUND(Tablero!B52,0),0) -> 0
P35: =IF(Tablero!A53="","",SUBSTITUTE(Tablero!A53,"EJEMPLO ","")) | Q35: =IF(Tablero!C53="Verde",ROUND(Tablero!B53,0),0) -> 0 | R35: =IF(Tablero!C53="Amarillo",ROUND(Tablero!B53,0),0) -> 0 | S35: =IF(Tablero!C53="Rojo",ROUND(Tablero!B53,0),0) -> 0
P36: =IF(Tablero!A54="","",SUBSTITUTE(Tablero!A54,"EJEMPLO ","")) | Q36: =IF(Tablero!C54="Verde",ROUND(Tablero!B54,0),0) -> 0 | R36: =IF(Tablero!C54="Amarillo",ROUND(Tablero!B54,0),0) -> 0 | S36: =IF(Tablero!C54="Rojo",ROUND(Tablero!B54,0),0) -> 0
P37: =IF(Tablero!A55="","",SUBSTITUTE(Tablero!A55,"EJEMPLO ","")) | Q37: =IF(Tablero!C55="Verde",ROUND(Tablero!B55,0),0) -> 0 | R37: =IF(Tablero!C55="Amarillo",ROUND(Tablero!B55,0),0) -> 0 | S37: =IF(Tablero!C55="Rojo",ROUND(Tablero!B55,0),0) -> 0
B43: =IF(COUNTA(Tablero!A26:A65)>12,"Hay más de 12 docentes: el gráfico muestra los 12 primeros. La lista completa está en la hoja Tablero.","El gráfico muestra hasta 12 docentes; la lista completa está en la hoja Tablero.") -> El gráfico muestra hasta 12 docentes; la lista completa está en la hoja Tablero.
H44: ¿EN QUÉ SOMOS BUENOS Y QUÉ FALTA?
B45: DOCENTES POR COLOR | H45: =IFERROR("Lo que mejor hacemos: "&INDEX(Dashboard!$U$15:$U$24,MATCH(MAX(Dashboard!$Y$15:$Y$24),Dashboard!$Y$15:$Y$24,0))&" ("&MAX(Dashboard!$Y$15:$Y$24)&" de 100)","Sin datos") -> Lo que mejor hacemos: Inclusión (PIAR) (94 de 100)
H47: =IFERROR("Lo que más debemos mejorar: "&INDEX(Dashboard!$U$15:$U$24,MATCH(MIN(Dashboard!$Y$15:$Y$24),Dashboard!$Y$15:$Y$24,0))&" ("&MIN(Dashboard!$Y$15:$Y$24)&" de 100)","Sin datos") -> Lo que más debemos mejorar: Lo que aprendieron (71 de 100)
H49: =IFERROR("Componentes por debajo de 70: "&COUNTIF(Dashboard!$Y$15:$Y$24,"<70")&" de "&COUNT(Dashboard!$Y$15:$Y$24),"") -> Componentes por debajo de 70: 0 de 10
...

Sheet Instrucciones
A1: TABLERO DE INDICADORES — PLANEACIÓN ACADÉMICA CENTEC (multi-año: 2027, 2028, …)
A2: Complemento en Excel del aplicativo Sistema de Planeación CENTEC. Sirve para auditar en papel/Excel o cuando no haya conexión. Las fórmulas son las mismas del aplicativo (v1.0).
A4: CÓMO USARLO
A5: 1. Celdas con fondo amarillo = datos que usted digita. Celdas blancas = fórmulas (no las edite).
A6: 2. Hoja «Registro»: una fila por docente y período, para cualquier año (columna Año). Las filas marcadas EJEMPLO muestran el formato: bórrelas antes de usar.
A7: 3. Hoja «Parámetros»: pesos, umbrales y constantes. Si se cambian, suba la versión: el comparativo año a año dejará de ser comparable.
A8: 4. Hoja «Tablero»: resumen por docente y por año. Hoja «Año vs año»: compara automáticamente cada indicador entre 2027 y 2031.
A9: 5. Hoja «Lecciones»: decisiones del cierre anual (mantener / ajustar / eliminar / escalar) que alimentan la planeación del año siguiente.
A11: REGLAS QUE EVITAN EL SESGO
A12: • Ejecución < 60 % ⇒ rojo automático
A13: • PIAR < 80 % ⇒ máximo amarillo
A14: • Observación < 50 con 2 observadores ⇒ máximo amarillo
... A20: FUENTES: Teach (Banco Mundial) para observación; ganancia normalizada de Hake (1998) con contracción bayesiana; MET Project para pesos; EEF Toolkit y Dunlosky et al. (2013) para prácticas.

Sheet Parámetros
A1: Parámetro | B1: Valor | C1: Descripción / fuente
A2: C1 Planeación entregada a tiempo | B2: 0.05 | C2: planeadores entregados ≤ fecha límite / exigidos × 100
A3: C2 Ejecución de semanas planeadas | B3: 0.1 | C3: semanas con evidencia fechada (cuaderno/foto/SABI) que coincide con el planeador / semanas planeadas × 100
A4: C3 Cobertura de DBA | B4: 0.1 | C4: DBA con actividad y evaluación evidenciadas / DBA programados del período × 100
A5: C4 Calidad del planeador (R1) | B5: 0.1 | C5: suma de 8 criterios 0–3 / 24 × 100
A6: C5 Revisión de cuadernos (R2) | B6: 0.1 | C6: promedio rúbrica 0–3 en muestra aleatoria ciega → 0–100
A7: C6 Observación de aula (Teach) | B7: 0.2 | C7: (promedio 9 elementos − 1)/4 × 100; kappa ≥ 0,60; normalizado por observador
A8: C7 Ganancia de aprendizaje | B8: 0.15 | C8: g Hake por estudiante (pre ≤ 90) → contracción n/(n+10) → g 0,10=0 · 0,50=100
A9: C8 PIAR y ajustes razonables | B9: 0.1 | C9: ajustes verificados / ajustes comprometidos × 100
A10: C9 Proyectos transversales | B10: 0.05 | C10: fases INSPIRA–DISEÑA–EXPLORA–CREA–EVALÚA evidenciadas / 5 × 100
A11: C10 Percepción estudiantil (7Cs adaptada) | B11: 0.05 | C11: promedio 10 ítems → 0–100; solo si n ≥ 10; anónima
A12: Suma de pesos (debe ser 100 %) | B12: =SUM(B2:B11) -> 1 | C12: Control
A13: Umbral verde | B13: 85 | C13: ICD ≥ 85
A14: Umbral amarillo | B14: 70 | C14: ICD 70–84; menor que 70 = rojo
A15: Kappa mínimo | B15: 0.6 | C15: Landis y Koch: ≥ 0,61 sustancial. Por debajo, la observación no cuenta
A16: k de contracción | B16: 10 | C16: g ajustada = n/(n+k)·g + k/(n+k)·g media
A17: g media del colegio | B17: 0.3 | C17: Actualizar cada año con el promedio institucional real (2027: supuesto inicial, Hake 1998)
A18: Mínimo de fuentes | B18: 3 | C18: Sin 3 fuentes no se asigna color
A19: Versión de fórmulas | B19: 1.0 | C19: Cambia si cambia cualquier peso o fórmula

Sheet Registro
A1: Año | B1: Período | C1: Docente | D1: Grado / área | E1: Planeadores exigidos | F1: Planeadores a tiempo | G1: Semanas planeadas | H1: Semanas con evidencia | I1: DBA programados | J1: DBA evidenciados | K1: R1 total (0–24) | L1: R2 promedio (0–3) | M1: Teach promedio (1–5) | N1: κ ponderado (vacío si 1 obs.) | O1: Observadores distintos | P1: g promedio estudiantes | Q1: n estudiantes (pre ≤ 90) | R1: Ajustes PIAR comprometidos | S1: Ajustes PIAR verificados | T1: Fases transversales evidenciadas | U1: Proyectos asignados | V1: Encuesta promedio (1–5) | W1: n encuesta | X1: C1 Puntualidad | Y1: C2 Ejecución | Z1: C3 Cobertura DBA | AA1: C4 Planeador | AB1: C5 Cuadernos | AC1: C6 Observación | AD1: C7 Aprendizaje | AE1: C8 PIAR | AF1: C9 Transversal | AG1: C10 Estudiantes | AH1: Fuentes con dato | AI1: ICD sin tope | AJ1: Tope por reglas | AK1: ICD | AL1: Estado | AM1: Regla aplicada
A2: 2027 | B2: 1 | C2: EJEMPLO Docente A | D2: Transición | E2: 10 | F2: 10 | G2: 10 | H2: 10 | I2: 6 | J2: 6 | K2: 21 | L2: 2.7 | M2: 4.9 | N2: 0.82 | O2: 2 | P2: 0.46 | Q2: 29 | R2: 6 | S2: 6 | T2: 5 | U2: 1 | V2: 4.6 | W2: 20 | X2: =IF(N(E2)>0,MIN(100,F2/E2*100),"") -> 100 | Y2: =IF(N(G2)>0,MIN(100,H2/G2*100),"") -> 100 | Z2: =IF(N(I2)>0,MIN(100,J2/I2*100),"") -> 100 | AA2: =IF(K2="","",K2/24*100) -> 87.5 | AB2: =IF(L2="","",L2/3*100) -> 90 | AC2: =IF(OR(M2="",AND(N2<>"",N(N2)<Parámetros!$B$15)),"",MAX(0,MIN(100,(M2-1)/4*100))) -> 97.5 | AD2: =IF(OR(P2="",N(Q2)=0),"",MAX(0,MIN(100,((Q2/(Q2+Parámetros!$B$16))*P2+(Parámetros!$B$16/(Q2+Parámetros!$B$16))*Parámetros!$B$17-0.1)/0.4*100))) -> 79.74359 | AE2: =IF(N(R2)>0,MIN(100,S2/R2*100),"") -> 100 | AF2: =IF(N(U2)>0,MIN(100,T2/(U2*5)*100),"") -> 100 | AG2: =IF(OR(V2="",N(W2)<10),"",(V2-1)/4*100) -> 90 | AH2: =IF($C2="","",COUNT(X2:AG2)) -> 10 | AI2: =IF(OR($C2="",N(AH2)<Parámetros!$B$18),"",(IF(ISNUMBER(X2),X2*Parámetros!$B$2,0)+IF(ISNUMBER(Y2),Y2*Parámetros!$B$3,0)+IF(ISNUMBER(Z2),Z2*Parámetros!$B$4,0)+IF(ISNUMBER(AA2),AA2*Parámetros!$B$5,0)+IF(ISNUMBER(AB2),AB2*Parámetros!$B$6,0)+IF(ISNUMBER(AC2),AC2*Parámetros!$B$7,0)+IF(ISNUMBER(AD2),AD2*Parámetros!$B$8,0)+IF(ISNUMBER(AE2),AE2*Parámetros!$B$9,0)+IF(ISNUMBER(AF2),AF2*Parámetros!$B$10,0)+IF(ISNUMBER(AG2),AG2*Parámetros!$B$11,0))/(IF(ISNUMBER(X2),Parámetros!$B$2,0)+IF(ISNUMBER(Y2),Parámetros!$B$3,0)+IF(ISNUMBER(Z2),Parámetros!$B$4,0)+IF(ISNUMBER(AA2),Parámetros!$B$5,0)+IF(ISNUMBER(AB2),Parámetros!$B$6,0)+IF(ISNUMBER(AC2),Parámetros!$B$7,0)+IF(ISNUMBER(AD2),Parámetros!$B$8,0)+IF(ISNUMBER(AE2),Parámetros!$B$9,0)+IF(ISNUMBER(AF2),Parámetros!$B$10,0)+IF(ISNUMBER(AG2),Parámetros!$B$11,0))) -> 93.711538 | AJ2: =IF(AND(ISNUMBER(Y2),N(Y2)<60),69.9,IF(OR(AND(ISNUMBER(AE2),N(AE2)<80),AND(ISNUMBER(AC2),N(AC2)<50,N(O2)>=2)),84.9,100)) -> 100 | AK2: =IF(AI2="","",MIN(AI2,AJ2)) -> 93.711538 | AL2: =IF($C2="","",IF(AK2="","Gris — menos de 3 fuentes",IF(AND(AK2<Parámetros!$B$14,N2<>"",N(N2)<Parámetros!$B$15,N(Y2)>=60),"Gris — repetir observación",IF(AK2>=Parámetros!$B$13,"Verde",IF(AK2>=Parámetros!$B$14,"Amarillo","Rojo"))))) -> Verde | AM2: =IF($C2="","",IF(AND(ISNUMBER(Y2),N(Y2)<60),"Ejecución < 60 %: rojo automático",IF(AND(ISNUMBER(AE2),N(AE2)<80),"PIAR < 80 %: máximo amarillo",IF(AND(ISNUMBER(AC2),N(AC2)<50,N(O2)>=2),"Observación < 50: máximo amarillo",IF(AND(N2<>"",N(N2)<Parámetros!$B$15),"κ < 0,60: observación descartada, repetir","")))))
A3: 2027 | B3: 1 | C3: EJEMPLO Docente B | D3: 1° Integrada | E3: 10 | F3: 8 | G3: 10 | H3: 10 | I3: 6 | J3: 5 | K3: 19 | L3: 2.2 | M3: 4 | N3: 0.85 | O3: 2 | P3: 0.52 | Q3: 24 | T3: 4 | U3: 1 | V3: 4.3 | W3: 24 | X3: =IF(N(E3)>0,MIN(100,F3/E3*100),"") -> 80 | Y3: =IF(N(G3)>0,MIN(100,H3/G3*100),"") -> 100 | Z3: =IF(N(I3)>0,MIN(100,J3/I3*100),"") -> 83.333333 | AA3: =IF(K3="","",K3/24*100) -> 79.166667 | AB3: =IF(L3="","",L3/3*100) -> 73.333333 | AC3: =IF(OR(M3="",AND(N3<>"",N(N3)<Parámetros!$B$15)),"",MAX(0,MIN(100,(M3-1)/4*100))) -> 75 | AD3: =IF(OR(P3="",N(Q3)=0),"",MAX(0,MIN(100,((Q3/(Q3+Parámetros!$B$16))*P3+(Parámetros!$B$16/(Q3+Parámetros!$B$16))*Parámetros!$B$17-0.1)/0.4*100))) -> 88.823529 | AE3: =IF(N(R3)>0,MIN(100,S3/R3*100),"") | AF3: =IF(N(U3)>0,MIN(100,T3/(U3*5)*100),"") -> 80 | AG3: =IF(OR(V3="",N(W3)<10),"",(V3-1)/4*100) -> 82.5 | AH3: =IF($C3="","",COUNT(X3:AG3)) -> 9 | AI3: =IF(OR($C3="",N(AH3)<Parámetros!$B$18),"",(IF(ISNUMBER(X3),X3*Parámetros!$B$2,0)+IF(ISNUMBER(Y3),Y3*Parámetros!$B$3,0)+IF(ISNUMBER(Z3),Z3*Parámetros!$B$4,0)+IF(ISNUMBER(AA3),AA3*Parámetros!$B$5,0)+IF(ISNUMBER(AB3),AB3*Parámetros!$B$6,0)+IF(ISNUMBER(AC3),AC3*Parámetros!$B$7,0)+IF(ISNUMBER(AD3),AD3*Parámetros!$B$8,0)+IF(ISNUMBER(AE3),AE3*Parámetros!$B$9,0)+IF(ISNUMBER(AF3),AF3*Parámetros!$B$10,0)+IF(ISNUMBER(AG3),AG3*Parámetros!$B$11,0))/(IF(ISNUMBER(X3),Parámetros!$B$2,0)+IF(ISNUMBER(Y3),Parámetros!$B$3,0)+IF(ISNUMBER(Z3),Parámetros!$B$4,0)+IF(ISNUMBER(AA3),Parámetros!$B$5,0)+IF(ISNUMBER(AB3),Parámetros!$B$6,0)+IF(ISNUMBER(AC3),Parámetros!$B$7,0)+IF(ISNUMBER(AD3),Parámetros!$B$8,0)+IF(ISNUMBER(AE3),Parámetros!$B$9,0)+IF(ISNUMBER(AF3),Parámetros!$B$10,0)+IF(ISNUMBER(AG3),Parámetros!$B$11,0))) -> 82.257625 | AJ3: =IF(AND(ISNUMBER(Y3),N(Y3)<60),69.9,IF(OR(AND(ISNUMBER(AE3),N(AE3)<80),AND(ISNUMBER(AC3),N(AC3)<50,N(O3)>=2)),84.9,100)) -> 100 | AK3: =IF(AI3="","",MIN(AI3,AJ3)) -> 82.257625 | AL3: =IF($C3="","",IF(AK3="","Gris — menos de 3 fuentes",IF(AND(AK3<Parámetros!$B$14,N3<>"",N(N3)<Parámetros!$B$15,N(Y3)>=60),"Gris — repetir observación",IF(AK3>=Parámetros!$B$13,"Verde",IF(AK3>=Parámetros!$B$14,"Amarillo","Rojo"))))) -> Amarillo | AM3: =IF($C3="","",IF(AND(ISNUMBER(Y3),N(Y3)<60),"Ejecución < 60 %: rojo automático",IF(AND(ISNUMBER(AE3),N(AE3)<80),"PIAR < 80 %: máximo amarillo",IF(AND(ISNUMBER(AC3),N(AC3)<50,N(O3)>=2),"Observación < 50: máximo amarillo",IF(AND(N3<>"",N(N3)<Parámetros!$B$15),"κ < 0,60: observación descartada, repetir","")))))
A4: 2027 | B4: 1 | C4: EJEMPLO Docente C | D4: 3° Integrada | E4: 10 | F4: 7 | G4: 10 | H4: 7 | I4: 6 | J4: 5 | K4: 16 | L4: 2.1 | M4: 3.4 | N4: 0.73 | O4: 2 | P4: 0.44 | Q4: 27 | T4: 4 | U4: 1 | V4: 4 | W4: 23 | X4: =IF(N(E4)>0,MIN(100,F4/E4*100),"") -> 70 | Y4: =IF(N(G4)>0,MIN(100,H4/G4*100),"") -> 70 | Z4: =IF(N(I4)>0,MIN(100,J4/I4*100),"") -> 83.333333 | AA4: =IF(K4="","",K4/24*100) -> 66.666667 | AB4: =IF(L4="","",L4/3*100) -> 70 | AC4: =IF(OR(M4="",AND(N4<>"",N(N4)<Parámetros!$B$15)),"",MAX(0,MIN(100,(M4-1)/4*100))) -> 60 | AD4: =IF(OR(P4="",N(Q4)=0),"",MAX(0,MIN(100,((Q4/(Q4+Parámetros!$B$16))*P4+(Parámetros!$B$16/(Q4+Parámetros!$B$16))*Parámetros!$B$17-0.1)/0.4*100))) -> 75.540541 | AE4: =IF(N(R4)>0,MIN(100,S4/R4*100),"") | AF4: =IF(N(U4)>0,MIN(100,T4/(U4*5)*100),"") -> 80 | AG4: =IF(OR(V4="",N(W4)<10),"",(V4-1)/4*100) -> 75 | AH4: =IF($C4="","",COUNT(X4:AG4)) -> 9 | AI4: =IF(OR($C4="",N(AH4)<Parámetros!$B$18),"",(IF(ISNUMBER(X4),X4*Parámetros!$B$2,0)+IF(ISNUMBER(Y4),Y4*Parámetros!$B$3,0)+IF(ISNUMBER(Z4),Z4*Parámetros!$B$4,0)+IF(ISNUMBER(AA4),AA4*Parámetros!$B$5,0)+IF(ISNUMBER(AB4),AB4*Parámetros!$B$6,0)+IF(ISNUMBER(AC4),AC4*Parámetros!$B$7,0)+IF(ISNUMBER(AD4),AD4*Parámetros!$B$8,0)+IF(ISNUMBER(AE4),AE4*Parámetros!$B$9,0)+IF(ISNUMBER(AF4),AF4*Parámetros!$B$10,0)+IF(ISNUMBER(AG4),AG4*Parámetros!$B$11,0))/(IF(ISNUMBER(X4),Parámetros!$B$2,0)+IF(ISNUMBER(Y4),Parámetros!$B$3,0)+IF(ISNUMBER(Z4),Parámetros!$B$4,0)+IF(ISNUMBER(AA4),Parámetros!$B$5,0)+IF(ISNUMBER(AB4),Parámetros!$B$6,0)+IF(ISNUMBER(AC4),Parámetros!$B$7,0)+IF(ISNUMBER(AD4),Parámetros!$B$8,0)+IF(ISNUMBER(AE4),Parámetros!$B$9,0)+IF(ISNUMBER(AF4),Parámetros!$B$10,0)+IF(ISNUMBER(AG4),Parámetros!$B$11,0))) -> 70.645646 | AJ4: =IF(AND(ISNUMBER(Y4),N(Y4)<60),69.9,IF(OR(AND(ISNUMBER(AE4),N(AE4)<80),AND(ISNUMBER(AC4),N(AC4)<50,N(O4)>=2)),84.9,100)) -> 100 | AK4: =IF(AI4="","",MIN(AI4,AJ4)) -> 70.645646 | AL4: =IF($C4="","",IF(AK4="","Gris — menos de 3 fuentes",IF(AND(AK4<Parámetros!$B$14,N4<>"",N(N4)<Parámetros!$B$15,N(Y4)>=60),"Gris — repetir observación",IF(AK4>=Parámetros!$B$13,"Verde",IF(AK4>=Parámetros!$B$14,"Amarillo","Rojo"))))) -> Amarillo | AM4: =IF($C4="","",IF(AND(ISNUMBER(Y4),N(Y4)<60),"Ejecución < 60 %: rojo automático",IF(AND(ISNUMBER(AE4),N(AE4)<80),"PIAR < 80 %: máximo amarillo",IF(AND(ISNUMBER(AC4),N(AC4)<50,N(O4)>=2),"Observación < 50: máximo amarillo",IF(AND(N4<>"",N(N4)<Parámetros!$B$15),"κ < 0,60: observación descartada, repetir","")))))
A5: 2027 | B5: 1 | C5: EJEMPLO Docente D | D5: 5° Integrada | E5: 10 | F5: 10 | G5: 10 | H5: 10 | I5: 6 | J5: 6 | K5: 20 | L5: 2.8 | M5: 4.3 | N5: 0.9 | O5: 2 | P5: 0.47 | Q5: 24 | R5: 6 | S5: 6 | T5: 5 | U5: 1 | V5: 4.5 | W5: 26 | X5: =IF(N(E5)>0,MIN(100,F5/E5*100),"") -> 100 | Y5: =IF(N(G5)>0,MIN(100,H5/G5*100),"") -> 100 | Z5: =IF(N(I5)>0,MIN(100,J5/I5*100),"") -> 100 | AA5: =IF(K5="","",K5/24*100) -> 83.333333 | AB5: =IF(L5="","",L5/3*100) -> 93.333333 | AC5: =IF(OR(M5="",AND(N5<>"",N(N5)<Parámetros!$B$15)),"",MAX(0,MIN(100,(M5-1)/4*100))) -> 82.5 | AD5: =IF(OR(P5="",N(Q5)=0),"",MAX(0,MIN(100,((Q5/(Q5+Parámetros!$B$16))*P5+(Parámetros!$B$16/(Q5+Parámetros!$B$16))*Parámetros!$B$17-0.1)/0.4*100))) -> 80 | AE5: =IF(N(R5)>0,MIN(100,S5/R5*100),"") -> 100 | AF5: =IF(N(U5)>0,MIN(100,T5/(U5*5)*100),"") -> 100 | AG5: =IF(OR(V5="",N(W5)<10),"",(V5-1)/4*100) -> 87.5 | AH5: =IF($C5="","",COUNT(X5:AG5)) -> 10 | AI5: =IF(OR($C5="",N(AH5)<Parámetros!$B$18),"",(IF(ISNUMBER(X5),X5*Parámetros!$B$2,0)+IF(ISNUMBER(Y5),Y5*Parámetros!$B$3,0)+IF(ISNUMBER(Z5),Z5*Parámetros!$B$4,0)+IF(ISNUMBER(AA5),AA5*Parámetros!$B$5,0)+IF(ISNUMBER(AB5),AB5*Parámetros!$B$6,0)+IF(ISNUMBER(AC5),AC5*Parámetros!$B$7,0)+IF(ISNUMBER(AD5),AD5*Parámetros!$B$8,0)+IF(ISNUMBER(AE5),AE5*Parámetros!$B$9,0)+IF(ISNUMBER(AF5),AF5*Parámetros!$B$10,0)+IF(ISNUMBER(AG5),AG5*Parámetros!$B$11,0))/(IF(ISNUMBER(X5),Parámetros!$B$2,0)+IF(ISNUMBER(Y5),Parámetros!$B$3,0)+IF(ISNUMBER(Z5),Parámetros!$B$4,0)+IF(ISNUMBER(AA5),Parámetros!$B$5,0)+IF(ISNUMBER(AB5),Parámetros!$B$6,0)+IF(ISNUMBER(AC5),Parámetros!$B$7,0)+IF(ISNUMBER(AD5),Parámetros!$B$8,0)+IF(ISNUMBER(AE5),Parámetros!$B$9,0)+IF(ISNUMBER(AF5),Parámetros!$B$10,0)+IF(ISNUMBER(AG5),Parámetros!$B$11,0))) -> 90.541667 | AJ5: =IF(AND(ISNUMBER(Y5),N(Y5)<60),69.9,IF(OR(AND(ISNUMBER(AE5),N(AE5)<80),AND(ISNUMBER(AC5),N(AC5)<50,N(O5)>=2)),84.9,100)) -> 100 | AK5: =IF(AI5="","",MIN(AI5,AJ5)) -> 90.541667 | AL5: =IF($C5="","",IF(AK5="","Gris — menos de 3 fuentes",IF(AND(AK5<Parámetros!$B$14,N5<>"",N(N5)<Parámetros!$B$15,N(Y5)>=60),"Gris — repetir observación",IF(AK5>=Parámetros!$B$13,"Verde",IF(AK5>=Parámetros!$B$14,"Amarillo","Rojo"))))) -> Verde | AM5: =IF($C5="","",IF(AND(ISNUMBER(Y5),N(Y5)<60),"Ejecución < 60 %: rojo automático",IF(AND(ISNUMBER(AE5),N(AE5)<80),"PIAR < 80 %: máximo amarillo",IF(AND(ISNUMBER(AC5),N(AC5)<50,N(O5)>=2),"Observación < 50: máximo amarillo",IF(AND(N5<>"",N(N5)<Parámetros!$B$15),"κ < 0,60: observación descartada, repetir","")))))
A6: 2027 | B6: 1 | C6: EJEMPLO Docente E | D6: Inglés primaria | E6: 10 | F6: 8 | G6: 10 | H6: 9 | I6: 6 | J6: 5 | K6: 17 | L6: 2 | M6: 3.7 | N6: 0.8 | O6: 2 | P6: 0.36 | Q6: 30 | T6: 4 | U6: 1 | V6: 4.2 | W6: 27 | X6: =IF(N(E6)>0,MIN(100,F6/E6*100),"") -> 80 | Y6: =IF(N(G6)>0,MIN(100,H6/G6*100),"") -> 90 | Z6: =IF(N(I6)>0,MIN(100,J6/I6*100),"") -> 83.333333 | AA6: =IF(K6="","",K6/24*100) -> 70.833333 | AB6: =IF(L6="","",L6/3*100) -> 66.666667 | AC6: =IF(OR(M6="",AND(N6<>"",N(N6)<Parámetros!$B$15)),"",MAX(0,MIN(100,(M6-1)/4*100))) -> 67.5 | AD6: =IF(OR(P6="",N(Q6)=0),"",MAX(0,MIN(100,((Q6/(Q6+Parámetros!$B$16))*P6+(Parámetros!$B$16/(Q6+Parámetros!$B$16))*Parámetros!$B$17-0.1)/0.4*100))) -> 61.25 | AE6: =IF(N(R6)>0,MIN(100,S6/R6*100),"") | AF6: =IF(N(U6)>0,MIN(100,T6/(U6*5)*100),"") -> 80 | AG6: =IF(OR(V6="",N(W6)<10),"",(V6-1)/4*100) -> 80 | AH6: =IF($C6="","",COUNT(X6:AG6)) -> 9 | AI6: =IF(OR($C6="",N(AH6)<Parámetros!$B$18),"",(IF(ISNUMBER(X6),X6*Parámetros!$B$2,0)+IF(ISNUMBER(Y6),Y6*Parámetros!$B$3,0)+IF(ISNUMBER(Z6),Z6*Parámetros!$B$4,0)+IF(ISNUMBER(AA6),AA6*Parámetros!$B$5,0)+IF(ISNUMBER(AB6),AB6*Parámetros!$B$6,0)+IF(ISNUMBER(AC6),AC6*Parámetros!$B$7,0)+IF(ISNUMBER(AD6),AD6*Parámetros!$B$8,0)+IF(ISNUMBER(AE6),AE6*Parámetros!$B$9,0)+IF(ISNUMBER(AF6),AF6*Parámetros!$B$10,0)+IF(ISNUMBER(AG6),AG6*Parámetros!$B$11,0))/(IF(ISNUMBER(X6),Parámetros!$B$2,0)+IF(ISNUMBER(Y6),Parámetros!$B$3,0)+IF(ISNUMBER(Z6),Parámetros!$B$4,0)+IF(ISNUMBER(AA6),Parámetros!$B$5,0)+IF(ISNUMBER(AB6),Parámetros!$B$6,0)+IF(ISNUMBER(AC6),Parámetros!$B$7,0)+IF(ISNUMBER(AD6),Parámetros!$B$8,0)+IF(ISNUMBER(AE6),Parámetros!$B$9,0)+IF(ISNUMBER(AF6),Parámetros!$B$10,0)+IF(ISNUMBER(AG6),Parámetros!$B$11,0))) -> 73.078704 | AJ6: =IF(AND(ISNUMBER(Y6),N(Y6)<60),69.9,IF(OR(AND(ISNUMBER(AE6),N(AE6)<80),AND(ISNUMBER(AC6),N(AC6)<50,N(O6)>=2)),84.9,100)) -> 100 | AK6: =IF(AI6="","",MIN(AI6,AJ6)) -> 73.078704 | AL6: =IF($C6="","",IF(AK6="","Gris — menos de 3 fuentes",IF(AND(AK6<Parámetros!$B$14,N6<>"",N(N6)<Parámetros!$B$15,N(Y6)>=60),"Gris — repetir observación",IF(AK6>=Parámetros!$B$13,"Verde",IF(AK6>=Parámetros!$B$14,"Amarillo","Rojo"))))) -> Amarillo | AM6: =IF($C6="","",IF(AND(ISNUMBER(Y6),N(Y6)<60),"Ejecución < 60 %: rojo automático",IF(AND(ISNUMBER(AE6),N(AE6)<80),"PIAR < 80 %: máximo amarillo",IF(AND(ISNUMBER(AC6),N(AC6)<50,N(O6)>=2),"Observación < 50: máximo amarillo",IF(AND(N6<>"",N(N6)<Parámetros!$B$15),"κ < 0,60: observación descartada, repetir","")))))
A7: 2027 | B7: 1 | C7: EJEMPLO Docente F | D7: Matemáticas 6°–9° | E7: 10 | F7: 6 | G7: 10 | H7: 7 | I7: 6 | J7: 3 | K7: 11 | L7: 1.3 | M7: 2.7 | N7: 0.71 | O7: 2 | P7: 0.36 | Q7: 30 | T7: 3 | U7: 1 | V7: 3.7 | W7: 19 | X7: =IF(N(E7)>0,MIN(100,F7/E7*100),"") -> 60 | Y7: =IF(N(G7)>0,MIN(100,H7/G7*100),"") -> 70 | Z7: =IF(N(I7)>0,MIN(100,J7/I7*100),"") -> 50 | AA7: =IF(K7="","",K7/24*100) -> 45.833333 | AB7: =IF(L7="","",L7/3*100) -> 43.333333 | AC7: =IF(OR(M7="",AND(N7<>"",N(N7)<Parámetros!$B$15)),"",MAX(0,MIN(100,(M7-1)/4*100))) -> 42.5 | AD7: =IF(OR(P7="",N(Q7)=0),"",MAX(0,MIN(100,((Q7/(Q7+Parámetros!$B$16))*P7+(Parámetros!$B$16/(Q7+Parámetros!$B$16))*Parámetros!$B$17-0.1)/0.4*100))) -> 61.25 | AE7: =IF(N(R7)>0,MIN(100,S7/R7*100),"") | AF7: =IF(N(U7)>0,MIN(100,T7/(U7*5)*100),"") -> 60 | AG7: =IF(OR(V7="",N(W7)<10),"",(V7-1)/4*100) -> 67.5 | AH7: =IF($C7="","",COUNT(X7:AG7)) -> 9 | AI7: =IF(OR($C7="",N(AH7)<Parámetros!$B$18),"",(IF(ISNUMBER(X7),X7*Parámetros!$B$2,0)+IF(ISNUMBER(Y7),Y7*Parámetros!$B$3,0)+IF(ISNUMBER(Z7),Z7*Parámetros!$B$4,0)+IF(ISNUMBER(AA7),AA7*Parámetros!$B$5,0)+IF(ISNUMBER(AB7),AB7*Parámetros!$B$6,0)+IF(ISNUMBER(AC7),AC7*Parámetros!$B$7,0)+IF(ISNUMBER(AD7),AD7*Parámetros!$B$8,0)+IF(ISNUMBER(AE7),AE7*Parámetros!$B$9,0)+IF(ISNUMBER(AF7),AF7*Parámetros!$B$10,0)+IF(ISNUMBER(AG7),AG7*Parámetros!$B$11,0))/(IF(ISNUMBER(X7),Parámetros!$B$2,0)+IF(ISNUMBER(Y7),Parámetros!$B$3,0)+IF(ISNUMBER(Z7),Parámetros!$B$4,0)+IF(ISNUMBER(AA7),Parámetros!$B$5,0)+IF(ISNUMBER(AB7),Parámetros!$B$6,0)+IF(ISNUMBER(AC7),Parámetros!$B$7,0)+IF(ISNUMBER(AD7),Parámetros!$B$8,0)+IF(ISNUMBER(AE7),Parámetros!$B$9,0)+IF(ISNUMBER(AF7),Parámetros!$B$10,0)+IF(ISNUMBER(AG7),Parámetros!$B$11,0))) -> 53.310185 | AJ7: =IF(AND(ISNUMBER(Y7),N(Y7)<60),69.9,IF(OR(AND(ISNUMBER(AE7),N(AE7)<80),AND(ISNUMBER(AC7),N(AC7)<50,N(O7)>=2)),84.9,100)) -> 84.9 | AK7: =IF(AI7="","",MIN(AI7,AJ7)) -> 53.310185 | AL7: =IF($C7="","",IF(AK7="","Gris — menos de 3 fuentes",IF(AND(AK7<Parámetros!$B$14,N7<>"",N(N7)<Parámetros!$B$15,N(Y7)>=60),"Gris — repetir observación",IF(AK7>=Parámetros!$B$13,"Verde",IF(AK7>=Parámetros!$B$14,"Amarillo","Rojo"))))) -> Rojo | AM7: =IF($C7="","",IF(AND(ISNUMBER(Y7),N(Y7)<60),"Ejecución < 60 %: rojo automático",IF(AND(ISNUMBER(AE7),N(AE7)<80),"PIAR < 80 %: máximo amarillo",IF(AND(ISNUMBER(AC7),N(AC7)<50,N(O7)>=2),"Observación < 50: máximo amarillo",IF(AND(N7<>"",N(N7)<Parámetros!$B$15),"κ < 0,60: observación descartada, repetir",""))))) -> Observación < 50: máximo amarillo
A8: 2027 | B8: 1 | C8: EJEMPLO Docente G | D8: Lenguaje 6°–11° | E8: 10 | F8: 9 | G8: 10 | H8: 10 | I8: 6 | J8: 5 | K8: 19 | L8: 2.5 | M8: 4.1 | N8: 0.76 | O8: 2 | P8: 0.45 | Q8: 25 | R8: 6 | S8: 5 | T8: 5 | U8: 1 | V8: 4.4 | W8: 26 | X8: =IF(N(E8)>0,MIN(100,F8/E8*100),"") -> 90 | Y8: =IF(N(G8)>0,MIN(100,H8/G8*100),"") -> 100 | Z8: =IF(N(I8)>0,MIN(100,J8/I8*100),"") -> 83.333333 | AA8: =IF(K8="","",K8/24*100) -> 79.166667 | AB8: =IF(L8="","",L8/3*100) -> 83.333333 | AC8: =IF(OR(M8="",AND(N8<>"",N(N8)<Parámetros!$B$15)),"",MAX(0,MIN(100,(M8-1)/4*100))) -> 77.5 | AD8: =IF(OR(P8="",N(Q8)=0),"",MAX(0,MIN(100,((Q8/(Q8+Parámetros!$B$16))*P8+(Parámetros!$B$16/(Q8+Parámetros!$B$16))*Parámetros!$B$17-0.1)/0.4*100))) -> 76.785714 | AE8: =IF(N(R8)>0,MIN(100,S8/R8*100),"") -> 83.333333 | AF8: =IF(N(U8)>0,MIN(100,T8/(U8*5)*100),"") -> 100 | AG8: =IF(OR(V8="",N(W8)<10),"",(V8-1)/4*100) -> 85 | AH8: =IF($C8="","",COUNT(X8:AG8)) -> 10 | AI8: =IF(OR($C8="",N(AH8)<Parámetros!$B$18),"",(IF(ISNUMBER(X8),X8*Parámetros!$B$2,0)+IF(ISNUMBER(Y8),Y8*Parámetros!$B$3,0)+IF(ISNUMBER(Z8),Z8*Parámetros!$B$4,0)+IF(ISNUMBER(AA8),AA8*Parámetros!$B$5,0)+IF(ISNUMBER(AB8),AB8*Parámetros!$B$6,0)+IF(ISNUMBER(AC8),AC8*Parámetros!$B$7,0)+IF(ISNUMBER(AD8),AD8*Parámetros!$B$8,0)+IF(ISNUMBER(AE8),AE8*Parámetros!$B$9,0)+IF(ISNUMBER(AF8),AF8*Parámetros!$B$10,0)+IF(ISNUMBER(AG8),AG8*Parámetros!$B$11,0))/(IF(ISNUMBER(X8),Parámetros!$B$2,0)+IF(ISNUMBER(Y8),Parámetros!$B$3,0)+IF(ISNUMBER(Z8),Parámetros!$B$4,0)+IF(ISNUMBER(AA8),Parámetros!$B$5,0)+IF(ISNUMBER(AB8),Parámetros!$B$6,0)+IF(ISNUMBER(AC8),Parámetros!$B$7,0)+IF(ISNUMBER(AD8),Parámetros!$B$8,0)+IF(ISNUMBER(AE8),Parámetros!$B$9,0)+IF(ISNUMBER(AF8),Parámetros!$B$10,0)+IF(ISNUMBER(AG8),Parámetros!$B$11,0))) -> 83.684524 | AJ8: =IF(AND(ISNUMBER(Y8),N(Y8)<60),69.9,IF(OR(AND(ISNUMBER(AE8),N(AE8)<80),AND(ISNUMBER(AC8),N(AC8)<50,N(O8)>=2)),84.9,100)) -> 100 | AK8: =IF(AI8="","",MIN(AI8,AJ8)) -> 83.684524 | AL8: =IF($C8="","",IF(AK8="","Gris — menos de 3 fuentes",IF(AND(AK8<Parámetros!$B$14,N8<>"",N(N8)<Parámetros!$B$15,N(Y8)>=60),"Gris — repetir observación",IF(AK8>=Parámetros!$B$13,"Verde",IF(AK8>=Parámetros!$B$14,"Amarillo","Rojo"))))) -> Amarillo | AM8: =IF($C8="","",IF(AND(ISNUMBER(Y8),N(Y8)<60),"Ejecución < 60 %: rojo automático",IF(AND(ISNUMBER(AE8),N(AE8)<80),"PIAR < 80 %: máximo amarillo",IF(AND(ISNUMBER(AC8),N(AC8)<50,N(O8)>=2),"Observación < 50: máximo amarillo",IF(AND(N8<>"",N(N8)<Parámetros!$B$15),"κ < 0,60: observación descartada, repetir","")))))
A9: 2027 | B9: 1 | C9: EJEMPLO Docente H | D9: Ciencias 6°–11° | E9: 10 | F9: 7 | G9: 10 | H9: 8 | I9: 6 | J9: 5 | K9: 15 | L9: 2.2 | M9: 3.7 | N9: 0.84 | O9: 2 | P9: 0.37 | Q9: 29 | T9: 4 | U9: 1 | V9: 4.1 | W9: 18 | X9: =IF(N(E9)>0,MIN(100,F9/E9*100),"") -> 70 | Y9: =IF(N(G9)>0,MIN(100,H9/G9*100),"") -> 80 | Z9: =IF(N(I9)>0,MIN(100,J9/I9*100),"") -> 83.333333 | AA9: =IF(K9="","",K9/24*100) -> 62.5 | AB9: =IF(L9="","",L9/3*100) -> 73.333333 | AC9: =IF(OR(M9="",AND(N9<>"",N(N9)<Parámetros!$B$15)),"",MAX(0,MIN(100,(M9-1)/4*100))) -> 67.5 | AD9: =IF(OR(P9="",N(Q9)=0),"",MAX(0,MIN(100,((Q9/(Q9+Parámetros!$B$16))*P9+(Parámetros!$B$16/(Q9+Parámetros!$B$16))*Parámetros!$B$17-0.1)/0.4*100))) -> 63.012821 | AE9: =IF(N(R9)>0,MIN(100,S9/R9*100),"") | AF9: =IF(N(U9)>0,MIN(100,T9/(U9*5)*100),"") -> 80 | AG9: =IF(OR(V9="",N(W9)<10),"",(V9-1)/4*100) -> 77.5 | AH9: =IF($C9="","",COUNT(X9:AG9)) -> 9 | AI9: =IF(OR($C9="",N(AH9)<Parámetros!$B$18),"",(IF(ISNUMBER(X9),X9*Parámetros!$B$2,0)+IF(ISNUMBER(Y9),Y9*Parámetros!$B$3,0)+IF(ISNUMBER(Z9),Z9*Parámetros!$B$4,0)+IF(ISNUMBER(AA9),AA9*Parámetros!$B$5,0)+IF(ISNUMBER(AB9),AB9*Parámetros!$B$6,0)+IF(ISNUMBER(AC9),AC9*Parámetros!$B$7,0)+IF(ISNUMBER(AD9),AD9*Parámetros!$B$8,0)+IF(ISNUMBER(AE9),AE9*Parámetros!$B$9,0)+IF(ISNUMBER(AF9),AF9*Parámetros!$B$10,0)+IF(ISNUMBER(AG9),AG9*Parámetros!$B$11,0))/(IF(ISNUMBER(X9),Parámetros!$B$2,0)+IF(ISNUMBER(Y9),Parámetros!$B$3,0)+IF(ISNUMBER(Z9),Parámetros!$B$4,0)+IF(ISNUMBER(AA9),Parámetros!$B$5,0)+IF(ISNUMBER(AB9),Parámetros!$B$6,0)+IF(ISNUMBER(AC9),Parámetros!$B$7,0)+IF(ISNUMBER(AD9),Parámetros!$B$8,0)+IF(ISNUMBER(AE9),Parámetros!$B$9,0)+IF(ISNUMBER(AF9),Parámetros!$B$10,0)+IF(ISNUMBER(AG9),Parámetros!$B$11,0))) -> 71.381766 | AJ9: =IF(AND(ISNUMBER(Y9),N(Y9)<60),69.9,IF(OR(AND(ISNUMBER(AE9),N(AE9)<80),AND(ISNUMBER(AC9),N(AC9)<50,N(O9)>=2)),84.9,100)) -> 100 | AK9: =IF(AI9="","",MIN(AI9,AJ9)) -> 71.381766 | AL9: =IF($C9="","",IF(AK9="","Gris — menos de 3 fuentes",IF(AND(AK9<Parámetros!$B$14,N9<>"",N(N9)<Parámetros!$B$15,N(Y9)>=60),"Gris — repetir observación",IF(AK9>=Parámetros!$B$13,"Verde",IF(AK9>=Parámetros!$B$14,"Amarillo","Rojo"))))) -> Amarillo | AM9: =IF($C9="","",IF(AND(ISNUMBER(Y9),N(Y9)<60),"Ejecución < 60 %: rojo automático",IF(AND(ISNUMBER(AE9),N(AE9)<80),"PIAR < 80 %: máximo amarillo",IF(AND(ISNUMBER(AC9),N(AC9)<50,N(O9)>=2),"Observación < 50: máximo amarillo",IF(AND(N9<>"",N(N9)<Parámetros!$B$15),"κ < 0,60: observación descartada, repetir","")))))
A10: 2027 | B10: 2 | C10: EJEMPLO Docente A | D10: Transición | E10: 10 | F10: 10 | G10: 10 | H10: 10 | I10: 6 | J10: 6 | K10: 23 | L10: 2.8 | M10: 4.5 | N10: 0.91 | O10: 2 | P10: 0.54 | Q10: 21 | R10: 6 | S10: 6 | T10: 5 | U10: 1 | X10: =IF(N(E10)>0,MIN(100,F10/E10*100),"") -> 100 | Y10: =IF(N(G10)>0,MIN(100,H10/G10*100),"") -> 100 | Z10: =IF(N(I10)>0,MIN(100,J10/I10*100),"") -> 100 | AA10: =IF(K10="","",K10/24*100) -> 95.833333 | AB10: =IF(L10="","",L10/3*100) -> 93.333333 | AC10: =IF(OR(M10="",AND(N10<>"",N(N10)<Parámetros!$B$15)),"",MAX(0,MIN(100,(M10-1)/4*100))) -> 87.5 | AD10: =IF(OR(P10="",N(Q10)=0),"",MAX(0,MIN(100,((Q10/(Q10+Parámetros!$B$16))*P10+(Parámetros!$B$16/(Q10+Parámetros!$B$16))*Parámetros!$B$17-0.1)/0.4*100))) -> 90.645161 | AE10: =IF(N(R10)>0,MIN(100,S10/R10*100),"") -> 100 | AF10: =IF(N(U10)>0,MIN(100,T10/(U10*5)*100),"") -> 100 | AG10: =IF(OR(V10="",N(W10)<10),"",(V10-1)/4*100) | AH10: =IF($C10="","",COUNT(X10:AG10)) -> 9 | AI10: =IF(OR($C10="",N(AH10)<Parámetros!$B$18),"",(IF(ISNUMBER(X10),X10*Parámetros!$B$2,0)+IF(ISNUMBER(Y10),Y10*Parámetros!$B$3,0)+IF(ISNUMBER(Z10),Z10*Parámetros!$B$4,0)+IF(ISNUMBER(AA10),AA10*Parámetros!$B$5,0)+IF(ISNUMBER(AB10),AB10*Parámetros!$B$6,0)+IF(ISNUMBER(AC10),AC10*Parámetros!$B$7,0)+IF(ISNUMBER(AD10),AD10*Parámetros!$B$8,0)+IF(ISNUMBER(AE10),AE10*Parámetros!$B$9,0)+IF(ISNUMBER(AF10),AF10*Parámetros!$B$10,0)+IF(ISNUMBER(AG10),AG10*Parámetros!$B$11,0))/(IF(ISNUMBER(X10),Parámetros!$B$2,0)+IF(ISNUMBER(Y10),Parámetros!$B$3,0)+IF(ISNUMBER(Z10),Parámetros!$B$4,0)+IF(ISNUMBER(AA10),Parámetros!$B$5,0)+IF(ISNUMBER(AB10),Parámetros!$B$6,0)+IF(ISNUMBER(AC10),Parámetros!$B$7,0)+IF(ISNUMBER(AD10),Parámetros!$B$8,0)+IF(ISNUMBER(AE10),Parámetros!$B$9,0)+IF(ISNUMBER(AF10),Parámetros!$B$10,0)+IF(ISNUMBER(AG10),Parámetros!$B$11,0))) -> 94.75099 | AJ10: =IF(AND(ISNUMBER(Y10),N(Y10)<60),69.9,IF(OR(AND(ISNUMBER(AE10),N(AE10)<80),AND(ISNUMBER(AC10),N(AC10)<50,N(O10)>=2)),84.9,100)) -> 100 | AK10: =IF(AI10="","",MIN(AI10,AJ10)) -> 94.75099 | AL10: =IF($C10="","",IF(AK10="","Gris — menos de 3 fuentes",IF(AND(AK10<Parámetros!$B$14,N10<>"",N(N10)<Parámetros!$B$15,N(Y10)>=60),"Gris — repetir observación",IF(AK10>=Parámetros!$B$13,"Verde",IF(AK10>=Parámetros!$B$14,"Amarillo","Rojo"))))) -> Verde | AM10: =IF($C10="","",IF(AND(ISNUMBER(Y10),N(Y10)<60),"Ejecución < 60 %: rojo automático",IF(AND(ISNUMBER(AE10),N(AE10)<80),"PIAR < 80 %: máximo amarillo",IF(AND(ISNUMBER(AC10),N(AC10)<50,N(O10)>=2),"Observación < 50: máximo amarillo",IF(AND(N10<>"",N(N10)<Parámetros!$B$15),"κ < 0,60: observación descartada, repetir","")))))
A11: 2027 | B11: 2 | C11: EJEMPLO Docente B | D11: 1° Integrada | E11: 10 | F11: 9 | G11: 10 | H11: 9 | I11: 6 | J11: 5 | K11: 19 | L11: 2.3 | M11: 4.4 | N11: 0.89 | O11: 2 | P11: 0.48 | Q11: 26 | T11: 4 | U11: 1 | X11: =IF(N(E11)>0,MIN(100,F11/E11*100),"") -> 90 | Y11: =IF(N(G11)>0,MIN(100,H11/G11*100),"") -> 90 | Z11: =IF(N(I11)>0,MIN(100,J11/I11*100),"") -> 83.333333 | AA11: =IF(K11="","",K11/24*100) -> 79.166667 | AB11: =IF(L11="","",L11/3*100) -> 76.666667 | AC11: =IF(OR(M11="",AND(N11<>"",N(N11)<Parámetros!$B$15)),"",MAX(0,MIN(100,(M11-1)/4*100))) -> 85 | AD11: =IF(OR(P11="",N(Q11)=0),"",MAX(0,MIN(100,((Q11/(Q11+Parámetros!$B$16))*P11+(Parámetros!$B$16/(Q11+Parámetros!$B$16))*Parámetros!$B$17-0.1)/0.4*100))) -> 82.5 | AE11: =IF(N(R11)>0,MIN(100,S11/R11*100),"") | AF11: =IF(N(U11)>0,MIN(100,T11/(U11*5)*100),"") -> 80 | AG11: =IF(OR(V11="",N(W11)<10),"",(V11-1)/4*100) | AH11: =IF($C11="","",COUNT(X11:AG11)) -> 8 | AI11: =IF(OR($C11="",N(AH11)<Parámetros!$B$18),"",(IF(ISNUMBER(X11),X11*Parámetros!$B$2,0)+IF(ISNUMBER(Y11),Y11*Parámetros!$B$3,0)+IF(ISNUMBER(Z11),Z11*Parámetros!$B$4,0)+IF(ISNUMBER(AA11),AA11*Parámetros!$B$5,0)+IF(ISNUMBER(AB11),AB11*Parámetros!$B$6,0)+IF(ISNUMBER(AC11),AC11*Parámetros!$B$7,0)+IF(ISNUMBER(AD11),AD11*Parámetros!$B$8,0)+IF(ISNUMBER(AE11),AE11*Parámetros!$B$9,0)+IF(ISNUMBER(AF11),AF11*Parámetros!$B$10,0)+IF(ISNUMBER(AG11),AG11*Parámetros!$B$11,0))/(IF(ISNUMBER(X11),Parámetros!$B$2,0)+IF(ISNUMBER(Y11),Parámetros!$B$3,0)+IF(ISNUMBER(Z11),Parámetros!$B$4,0)+IF(ISNUMBER(AA11),Parámetros!$B$5,0)+IF(ISNUMBER(AB11),Parámetros!$B$6,0)+IF(ISNUMBER(AC11),Parámetros!$B$7,0)+IF(ISNUMBER(AD11),Parámetros!$B$8,0)+IF(ISNUMBER(AE11),Parámetros!$B$9,0)+IF(ISNUMBER(AF11),Parámetros!$B$10,0)+IF(ISNUMBER(AG11),Parámetros!$B$11,0))) -> 83.284314 | AJ11: =IF(AND(ISNUMBER(Y11),N(Y11)<60),69.9,IF(OR(AND(ISNUMBER(AE11),N(AE11)<80),AND(ISNUMBER(AC11),N(AC11)<50,N(O11)>=2)),84.9,100)) -> 100 | AK11: =IF(AI11="","",MIN(AI11,AJ11)) -> 83.284314 | AL11: =IF($C11="","",IF(AK11="","Gris — menos de 3 fuentes",IF(AND(AK11<Parámetros!$B$14,N11<>"",N(N11)<Parámetros!$B$15,N(Y11)>=60),"Gris — repetir observación",IF(AK11>=Parámetros!$B$13,"Verde",IF(AK11>=Parámetros!$B$14,"Amarillo","Rojo"))))) -> Amarillo | AM11: =IF($C11="","",IF(AND(ISNUMBER(Y11),N(Y11)<60),"Ejecución < 60 %: rojo automático",IF(AND(ISNUMBER(AE11),N(AE11)<80),"PIAR < 80 %: máximo amarillo",IF(AND(ISNUMBER(AC11),N(AC11)<50,N(O11)>=2),"Observación < 50: máximo amarillo",IF(AND(N11<>"",N(N11)<Parámetros!$B$15),"κ < 0,60: observación descartada, repetir","")))))
A12: 2027 | B12: 2 | C12: EJEMPLO Docente C | D12: 3° Integrada | E12: 10 | F12: 7 | G12: 10 | H12: 7 | I12: 6 | J12: 5 | K12: 15 | L12: 2 | M12: 3.5 | N12: 0.67 | O12: 2 | P12: 0.33 | Q12: 22 | T12: 4 | U12: 1 | X12: =IF(N(E12)>0,MIN(100,F12/E12*100),"") -> 70 | Y12: =IF(N(G12)>0,MIN(100,H12/G12*100),"") -> 70 | Z12: =IF(N(I12)>0,MIN(100,J12/I12*100),"") -> 83.333333 | AA12: =IF(K12="","",K12/24*100) -> 62.5 | AB12: =IF(L12="","",L12/3*100) -> 66.666667 | AC12: =IF(OR(M12="",AND(N12<>"",N(N12)<Parámetros!$B$15)),"",MAX(0,MIN(100,(M12-1)/4*100))) -> 62.5 | AD12: =IF(OR(P12="",N(Q12)=0),"",MAX(0,MIN(100,((Q12/(Q12+Parámetros!$B$16))*P12+(Parámetros!$B$16/(Q12+Parámetros!$B$16))*Parámetros!$B$17-0.1)/0.4*100))) -> 55.15625 | AE12: =IF(N(R12)>0,MIN(100,S12/R12*100),"") | AF12: =IF(N(U12)>0,MIN(100,T12/(U12*5)*100),"") -> 80 | AG12: =IF(OR(V12="",N(W12)<10),"",(V12-1)/4*100) | AH12: =IF($C12="","",COUNT(X12:AG12)) -> 8 | AI12: =IF(OR($C12="",N(AH12)<Parámetros!$B$18),"",(IF(ISNUMBER(X12),X12*Parámetros!$B$2,0)+IF(ISNUMBER(Y12),Y12*Parámetros!$B$3,0)+IF(ISNUMBER(Z12),Z12*Parámetros!$B$4,0)+IF(ISNUMBER(AA12),AA12*Parámetros!$B$5,0)+IF(ISNUMBER(AB12),AB12*Parámetros!$B$6,0)+IF(ISNUMBER(AC12),AC12*Parámetros!$B$7,0)+IF(ISNUMBER(AD12),AD12*Parámetros!$B$8,0)+IF(ISNUMBER(AE12),AE12*Parámetros!$B$9,0)+IF(ISNUMBER(AF12),AF12*Parámetros!$B$10,0)+IF(ISNUMBER(AG12),AG12*Parámetros!$B$11,0))/(IF(ISNUMBER(X12),Parámetros!$B$2,0)+IF(ISNUMBER(Y12),Parámetros!$B$3,0)+IF(ISNUMBER(Z12),Parámetros!$B$4,0)+IF(ISNUMBER(AA12),Parámetros!$B$5,0)+IF(ISNUMBER(AB12),Parámetros!$B$6,0)+IF(ISNUMBER(AC12),Parámetros!$B$7,0)+IF(ISNUMBER(AD12),Parámetros!$B$8,0)+IF(ISNUMBER(AE12),Parámetros!$B$9,0)+IF(ISNUMBER(AF12),Parámetros!$B$10,0)+IF(ISNUMBER(AG12),Parámetros!$B$11,0))) -> 66.498162 | AJ12: =IF(AND(ISNUMBER(Y12),N(Y12)<60),69.9,IF(OR(AND(ISNUMBER(AE12),N(AE12)<80),AND(ISNUMBER(AC12),N(AC12)<50,N(O12)>=2)),84.9,100)) -> 100 | AK12: =IF(AI12="","",MIN(AI12,AJ12)) -> 66.498162 | AL12: =IF($C12="","",IF(AK12="","Gris — menos de 3 fuentes",IF(AND(AK12<Parámetros!$B$14,N12<>"",N(N12)<Parámetros!$B$15,N(Y12)>=60),"Gris — repetir observación",IF(AK12>=Parámetros!$B$13,"Verde",IF(AK12>=Parámetros!$B$14,"Amarillo","Rojo"))))) -> Rojo | AM12: =IF($C12="","",IF(AND(ISNUMBER(Y12),N(Y12)<60),"Ejecución < 60 %: rojo automático",IF(AND(ISNUMBER(AE12),N(AE12)<80),"PIAR < 80 %: máximo amarillo",IF(AND(ISNUMBER(AC12),N(AC12)<50,N(O12)>=2),"Observación < 50: máximo amarillo",IF(AND(N12<>"",N(N12)<Parámetros!$B$15),"κ < 0,60: observación descartada, repetir","")))))
A13: 2027 | B13: 2 | C13: EJEMPLO Docente D | D13: 5° Integrada | E13: 10 | F13: 10 | G13: 10 | H13: 10 | I13: 6 | J13: 6 | K13: 20 | L13: 2.7 | M13: 4.3 | N13: 0.83 | O13: 2 | P13: 0.51 | Q13: 29 | R13: 6 | S13: 6 | T13: 5 | U13: 1 | X13: =IF(N(E13)>0,MIN(100,F13/E13*100),"") -> 100 | Y13: =IF(N(G13)>0,MIN(100,H13/G13*100),"") -> 100 | Z13: =IF(N(I13)>0,MIN(100,J13/I13*100),"") -> 100 | AA13: =IF(K13="","",K13/24*100) -> 83.333333 | AB13: =IF(L13="","",L13/3*100) -> 90 | AC13: =IF(OR(M13="",AND(N13<>"",N(N13)<Parámetros!$B$15)),"",MAX(0,MIN(100,(M13-1)/4*100))) -> 82.5 | AD13: =IF(OR(P13="",N(Q13)=0),"",MAX(0,MIN(100,((Q13/(Q13+Parámetros!$B$16))*P13+(Parámetros!$B$16/(Q13+Parámetros!$B$16))*Parámetros!$B$17-0.1)/0.4*100))) -> 89.038462 | AE13: =IF(N(R13)>0,MIN(100,S13/R13*100),"") -> 100 | AF13: =IF(N(U13)>0,MIN(100,T13/(U13*5)*100),"") -> 100 | AG13: =IF(OR(V13="",N(W13)<10),"",(V13-1)/4*100) | AH13: =IF($C13="","",COUNT(X13:AG13)) -> 9 | AI13: =IF(OR($C13="",N(AH13)<Parámetros!$B$18),"",(IF(ISNUMBER(X13),X13*Parámetros!$B$2,0)+IF(ISNUMBER(Y13),Y13*Parámetros!$B$3,0)+IF(ISNUMBER(Z13),Z13*Parámetros!$B$4,0)+IF(ISNUMBER(AA13),AA13*Parámetros!$B$5,0)+IF(ISNUMBER(AB13),AB13*Parámetros!$B$6,0)+IF(ISNUMBER(AC13),AC13*Parámetros!$B$7,0)+IF(ISNUMBER(AD13),AD13*Parámetros!$B$8,0)+IF(ISNUMBER(AE13),AE13*Parámetros!$B$9,0)+IF(ISNUMBER(AF13),AF13*Parámetros!$B$10,0)+IF(ISNUMBER(AG13),AG13*Parámetros!$B$11,0))/(IF(ISNUMBER(X13),Parámetros!$B$2,0)+IF(ISNUMBER(Y13),Parámetros!$B$3,0)+IF(ISNUMBER(Z13),Parámetros!$B$4,0)+IF(ISNUMBER(AA13),Parámetros!$B$5,0)+IF(ISNUMBER(AB13),Parámetros!$B$6,0)+IF(ISNUMBER(AC13),Parámetros!$B$7,0)+IF(ISNUMBER(AD13),Parámetros!$B$8,0)+IF(ISNUMBER(AE13),Parámetros!$B$9,0)+IF(ISNUMBER(AF13),Parámetros!$B$10,0)+IF(ISNUMBER(AG13),Parámetros!$B$11,0))) -> 91.778003 | AJ13: =IF(AND(ISNUMBER(Y13),N(Y13)<60),69.9,IF(OR(AND(ISNUMBER(AE13),N(AE13)<80),AND(ISNUMBER(AC13),N(AC13)<50,N(O13)>=2)),84.9,100)) -> 100 | AK13: =IF(AI13="","",MIN(AI13,AJ13)) -> 91.778003 | AL13: =IF($C13="","",IF(AK13="","Gris — menos de 3 fuentes",IF(AND(AK13<Parámetros!$B$14,N13<>"",N(N13)<Parámetros!$B$15,N(Y13)>=60),"Gris — repetir observación",IF(AK13>=Parámetros!$B$13,"Verde",IF(AK13>=Parámetros!$B$14,"Amarillo","Rojo"))))) -> Verde | AM13: =IF($C13="","",IF(AND(ISNUMBER(Y13),N(Y13)<60),"Ejecución < 60 %: rojo automático",IF(AND(ISNUMBER(AE13),N(AE13)<80),"PIAR < 80 %: máximo amarillo",IF(AND(ISNUMBER(AC13),N(AC13)<50,N(O13)>=2),"Observación < 50: máximo amarillo",IF(AND(N13<>"",N(N13)<Parámetros!$B$15),"κ < 0,60: observación descartada, repetir","")))))
A14: 2027 | B14: 2 | C14: EJEMPLO Docente E | D14: Inglés primaria | E14: 10 | F14: 8 | G14: 10 | H14: 9 | I14: 6 | J14: 5 | K14: 16 | L14: 2 | M14: 3.7 | N14: 0.77 | O14: 2 | P14: 0.35 | Q14: 20 | T14: 4 | U14: 1 | X14: =IF(N(E14)>0,MIN(100,F14/E14*100),"") -> 80 | Y14: =IF(N(G14)>0,MIN(100,H14/G14*100),"") -> 90 | Z14: =IF(N(I14)>0,MIN(100,J14/I14*100),"") -> 83.333333 | AA14: =IF(K14="","",K14/24*100) -> 66.666667 | AB14: =IF(L14="","",L14/3*100) -> 66.666667 | AC14: =IF(OR(M14="",AND(N14<>"",N(N14)<Parámetros!$B$15)),"",MAX(0,MIN(100,(M14-1)/4*100))) -> 67.5 | AD14: =IF(OR(P14="",N(Q14)=0),"",MAX(0,MIN(100,((Q14/(Q14+Parámetros!$B$16))*P14+(Parámetros!$B$16/(Q14+Parámetros!$B$16))*Parámetros!$B$17-0.1)/0.4*100))) -> 58.333333 | AE14: =IF(N(R14)>0,MIN(100,S14/R14*100),"") | AF14: =IF(N(U14)>0,MIN(100,T14/(U14*5)*100),"") -> 80 | AG14: =IF(OR(V14="",N(W14)<10),"",(V14-1)/4*100) | AH14: =IF($C14="","",COUNT(X14:AG14)) -> 8 | AI14: =IF(OR($C14="",N(AH14)<Parámetros!$B$18),"",(IF(ISNUMBER(X14),X14*Parámetros!$B$2,0)+IF(ISNUMBER(Y14),Y14*Parámetros!$B$3,0)+IF(ISNUMBER(Z14),Z14*Parámetros!$B$4,0)+IF(ISNUMBER(AA14),AA14*Parámetros!$B$5,0)+IF(ISNUMBER(AB14),AB14*Parámetros!$B$6,0)+IF(ISNUMBER(AC14),AC14*Parámetros!$B$7,0)+IF(ISNUMBER(AD14),AD14*Parámetros!$B$8,0)+IF(ISNUMBER(AE14),AE14*Parámetros!$B$9,0)+IF(ISNUMBER(AF14),AF14*Parámetros!$B$10,0)+IF(ISNUMBER(AG14),AG14*Parámetros!$B$11,0))/(IF(ISNUMBER(X14),Parámetros!$B$2,0)+IF(ISNUMBER(Y14),Parámetros!$B$3,0)+IF(ISNUMBER(Z14),Parámetros!$B$4,0)+IF(ISNUMBER(AA14),Parámetros!$B$5,0)+IF(ISNUMBER(AB14),Parámetros!$B$6,0)+IF(ISNUMBER(AC14),Parámetros!$B$7,0)+IF(ISNUMBER(AD14),Parámetros!$B$8,0)+IF(ISNUMBER(AE14),Parámetros!$B$9,0)+IF(ISNUMBER(AF14),Parámetros!$B$10,0)+IF(ISNUMBER(AG14),Parámetros!$B$11,0))) -> 71.666667 | AJ14: =IF(AND(ISNUMBER(Y14),N(Y14)<60),69.9,IF(OR(AND(ISNUMBER(AE14),N(AE14)<80),AND(ISNUMBER(AC14),N(AC14)<50,N(O14)>=2)),84.9,100)) -> 100 | AK14: =IF(AI14="","",MIN(AI14,AJ14)) -> 71.666667 | AL14: =IF($C14="","",IF(AK14="","Gris — menos de 3 fuentes",IF(AND(AK14<Parámetros!$B$14,N14<>"",N(N14)<Parámetros!$B$15,N(Y14)>=60),"Gris — repetir observación",IF(AK14>=Parámetros!$B$13,"Verde",IF(AK14>=Parámetros!$B$14,"Amarillo","Rojo"))))) -> Amarillo | AM14: =IF($C14="","",IF(AND(ISNUMBER(Y14),N(Y14)<60),"Ejecución < 60 %: rojo automático",IF(AND(ISNUMBER(AE14),N(AE14)<80),"PIAR < 80 %: máximo amarillo",IF(AND(ISNUMBER(AC14),N(AC14)<50,N(O14)>=2),"Observación < 50: máximo amarillo",IF(AND(N14<>"",N(N14)<Parámetros!$B$15),"κ < 0,60: observación descartada, repetir","")))))
A15: 2027 | B15: 2 | C15: EJEMPLO Docente F | D15: Matemáticas 6°–9° | E15: 10 | F15: 6 | G15: 10 | H15: 6 | I15: 6 | J15: 3 | K15: 12 | L15: 1.3 | M15: 3.2 | N15: 0.7 | O15: 2 | P15: 0.26 | Q15: 21 | T15: 3 | U15: 1 | X15: =IF(N(E15)>0,MIN(100,F15/E15*100),"") -> 60 | Y15: =IF(N(G15)>0,MIN(100,H15/G15*100),"") -> 60 | Z15: =IF(N(I15)>0,MIN(100,J15/I15*100),"") -> 50 | AA15: =IF(K15="","",K15/24*100) -> 50 | AB15: =IF(L15="","",L15/3*100) -> 43.333333 | AC15: =IF(OR(M15="",AND(N15<>"",N(N15)<Parámetros!$B$15)),"",MAX(0,MIN(100,(M15-1)/4*100))) -> 55 | AD15: =IF(OR(P15="",N(Q15)=0),"",MAX(0,MIN(100,((Q15/(Q15+Parámetros!$B$16))*P15+(Parámetros!$B$16/(Q15+Parámetros!$B$16))*Parámetros!$B$17-0.1)/0.4*100))) -> 43.225806 | AE15: =IF(N(R15)>0,MIN(100,S15/R15*100),"") | AF15: =IF(N(U15)>0,MIN(100,T15/(U15*5)*100),"") -> 60 | AG15: =IF(OR(V15="",N(W15)<10),"",(V15-1)/4*100) | AH15: =IF($C15="","",COUNT(X15:AG15)) -> 8 | AI15: =IF(OR($C15="",N(AH15)<Parámetros!$B$18),"",(IF(ISNUMBER(X15),X15*Parámetros!$B$2,0)+IF(ISNUMBER(Y15),Y15*Parámetros!$B$3,0)+IF(ISNUMBER(Z15),Z15*Parámetros!$B$4,0)+IF(ISNUMBER(AA15),AA15*Parámetros!$B$5,0)+IF(ISNUMBER(AB15),AB15*Parámetros!$B$6,0)+IF(ISNUMBER(AC15),AC15*Parámetros!$B$7,0)+IF(ISNUMBER(AD15),AD15*Parámetros!$B$8,0)+IF(ISNUMBER(AE15),AE15*Parámetros!$B$9,0)+IF(ISNUMBER(AF15),AF15*Parámetros!$B$10,0)+IF(ISNUMBER(AG15),AG15*Parámetros!$B$11,0))/(IF(ISNUMBER(X15),Parámetros!$B$2,0)+IF(ISNUMBER(Y15),Parámetros!$B$3,0)+IF(ISNUMBER(Z15),Parámetros!$B$4,0)+IF(ISNUMBER(AA15),Parámetros!$B$5,0)+IF(ISNUMBER(AB15),Parámetros!$B$6,0)+IF(ISNUMBER(AC15),Parámetros!$B$7,0)+IF(ISNUMBER(AD15),Parámetros!$B$8,0)+IF(ISNUMBER(AE15),Parámetros!$B$9,0)+IF(ISNUMBER(AF15),Parámetros!$B$10,0)+IF(ISNUMBER(AG15),Parámetros!$B$11,0))) -> 51.549652 | AJ15: =IF(AND(ISNUMBER(Y15),N(Y15)<60),69.9,IF(OR(AND(ISNUMBER(AE15),N(AE15)<80),AND(ISNUMBER(AC15),N(AC15)<50,N(O15)>=2)),84.9,100)) -> 100 | AK15: =IF(AI15="","",MIN(AI15,AJ15)) -> 51.549652 | AL15: =IF($C15="","",IF(AK15="","Gris — menos de 3 fuentes",IF(AND(AK15<Parámetros!$B$14,N15<>"",N(N15)<Parámetros!$B$15,N(Y15)>=60),"Gris — repetir observación",IF(AK15>=Parámetros!$B$13,"Verde",IF(AK15>=Parámetros!$B$14,"Amarillo","Rojo"))))) -> Rojo | AM15: =IF($C15="","",IF(AND(ISNUMBER(Y15),N(Y15)<60),"Ejecución < 60 %: rojo automático",IF(AND(ISNUMBER(AE15),N(AE15)<80),"PIAR < 80 %: máximo amarillo",IF(AND(ISNUMBER(AC15),N(AC15)<50,N(O15)>=2),"Observación < 50: máximo amarillo",IF(AND(N15<>"",N(N15)<Parámetros!$B$15),"κ < 0,60: observación descartada, repetir","")))))
A16: 2027 | B16: 2 | C16: EJEMPLO Docente G | D16: Lenguaje 6°–11° | E16: 10 | F16: 9 | G16: 10 | H16: 10 | I16: 6 | J16: 6 | K16: 21 | L16: 2.7 | M16: 4.4 | N16: 0.81 | O16: 2 | P16: 0.43 | Q16: 21 | R16: 6 | S16: 5 | T16: 5 | U16: 1 | X16: =IF(N(E16)>0,MIN(100,F16/E16*100),"") -> 90 | Y16: =IF(N(G16)>0,MIN(100,H16/G16*100),"") -> 100 | Z16: =IF(N(I16)>0,MIN(100,J16/I16*100),"") -> 100 | AA16: =IF(K16="","",K16/24*100) -> 87.5 | AB16: =IF(L16="","",L16/3*100) -> 90 | AC16: =IF(OR(M16="",AND(N16<>"",N(N16)<Parámetros!$B$15)),"",MAX(0,MIN(100,(M16-1)/4*100))) -> 85 | AD16: =IF(OR(P16="",N(Q16)=0),"",MAX(0,MIN(100,((Q16/(Q16+Parámetros!$B$16))*P16+(Parámetros!$B$16/(Q16+Parámetros!$B$16))*Parámetros!$B$17-0.1)/0.4*100))) -> 72.016129 | AE16: =IF(N(R16)>0,MIN(100,S16/R16*100),"") -> 83.333333 | AF16: =IF(N(U16)>0,MIN(100,T16/(U16*5)*100),"") -> 100 | AG16: =IF(OR(V16="",N(W16)<10),"",(V16-1)/4*100) | AH16: =IF($C16="","",COUNT(X16:AG16)) -> 9 | AI16: =IF(OR($C16="",N(AH16)<Parámetros!$B$18),"",(IF(ISNUMBER(X16),X16*Parámetros!$B$2,0)+IF(ISNUMBER(Y16),Y16*Parámetros!$B$3,0)+IF(ISNUMBER(Z16),Z16*Parámetros!$B$4,0)+IF(ISNUMBER(AA16),AA16*Parámetros!$B$5,0)+IF(ISNUMBER(AB16),AB16*Parámetros!$B$6,0)+IF(ISNUMBER(AC16),AC16*Parámetros!$B$7,0)+IF(ISNUMBER(AD16),AD16*Parámetros!$B$8,0)+IF(ISNUMBER(AE16),AE16*Parámetros!$B$9,0)+IF(ISNUMBER(AF16),AF16*Parámetros!$B$10,0)+IF(ISNUMBER(AG16),AG16*Parámetros!$B$11,0))/(IF(ISNUMBER(X16),Parámetros!$B$2,0)+IF(ISNUMBER(Y16),Parámetros!$B$3,0)+IF(ISNUMBER(Z16),Parámetros!$B$4,0)+IF(ISNUMBER(AA16),Parámetros!$B$5,0)+IF(ISNUMBER(AB16),Parámetros!$B$6,0)+IF(ISNUMBER(AC16),Parámetros!$B$7,0)+IF(ISNUMBER(AD16),Parámetros!$B$8,0)+IF(ISNUMBER(AE16),Parámetros!$B$9,0)+IF(ISNUMBER(AF16),Parámetros!$B$10,0)+IF(ISNUMBER(AG16),Parámetros!$B$11,0))) -> 87.774477 | AJ16: =IF(AND(ISNUMBER(Y16),N(Y16)<60),69.9,IF(OR(AND(ISNUMBER(AE16),N(AE16)<80),AND(ISNUMBER(AC16),N(AC16)<50,N(O16)>=2)),84.9,100)) -> 100 | AK16: =IF(AI16="","",MIN(AI16,AJ16)) -> 87.774477 | AL16: =IF($C16="","",IF(AK16="","Gris — menos de 3 fuentes",IF(AND(AK16<Parámetros!$B$14,N16<>"",N(N16)<Parámetros!$B$15,N(Y16)>=60),"Gris — repetir observación",IF(AK16>=Parámetros!$B$13,"Verde",IF(AK16>=Parámetros!$B$14,"Amarillo","Rojo"))))) -> Verde | AM16: =IF($C16="","",IF(AND(ISNUMBER(Y16),N(Y16)<60),"Ejecución < 60 %: rojo automático",IF(AND(ISNUMBER(AE16),N(AE16)<80),"PIAR < 80 %: máximo amarillo",IF(AND(ISNUMBER(AC16),N(AC16)<50,N(O16)>=2),"Observación < 50: máximo amarillo",IF(AND(N16<>"",N(N16)<Parámetros!$B$15),"κ < 0,60: observación descartada, repetir","")))))
A17: 2027 | B17: 2 | C17: EJEMPLO Docente H | D17: Ciencias 6°–11° | E17: 10 | F17: 8 | G17: 10 | H17: 9 | I17: 6 | J17: 5 | K17: 18 | L17: 2 | M17: 4 | N17: 0.8 | O17: 2 | P17: 0.36 | Q17: 29 | T17: 4 | U17: 1 | X17: =IF(N(E17)>0,MIN(100,F17/E17*100),"") -> 80 | Y17: =IF(N(G17)>0,MIN(100,H17/G17*100),"") -> 90 | Z17: =IF(N(I17)>0,MIN(100,J17/I17*100),"") -> 83.333333 | AA17: =IF(K17="","",K17/24*100) -> 75 | AB17: =IF(L17="","",L17/3*100) -> 66.666667 | AC17: =IF(OR(M17="",AND(N17<>"",N(N17)<Parámetros!$B$15)),"",MAX(0,MIN(100,(M17-1)/4*100))) -> 75 | AD17: =IF(OR(P17="",N(Q17)=0),"",MAX(0,MIN(100,((Q17/(Q17+Parámetros!$B$16))*P17+(Parámetros!$B$16/(Q17+Parámetros!$B$16))*Parámetros!$B$17-0.1)/0.4*100))) -> 61.153846 | AE17: =IF(N(R17)>0,MIN(100,S17/R17*100),"") | AF17: =IF(N(U17)>0,MIN(100,T17/(U17*5)*100),"") -> 80 | AG17: =IF(OR(V17="",N(W17)<10),"",(V17-1)/4*100) | AH17: =IF($C17="","",COUNT(X17:AG17)) -> 8 | AI17: =IF(OR($C17="",N(AH17)<Parámetros!$B$18),"",(IF(ISNUMBER(X17),X17*Parámetros!$B$2,0)+IF(ISNUMBER(Y17),Y17*Parámetros!$B$3,0)+IF(ISNUMBER(Z17),Z17*Parámetros!$B$4,0)+IF(ISNUMBER(AA17),AA17*Parámetros!$B$5,0)+IF(ISNUMBER(AB17),AB17*Parámetros!$B$6,0)+IF(ISNUMBER(AC17),AC17*Parámetros!$B$7,0)+IF(ISNUMBER(AD17),AD17*Parámetros!$B$8,0)+IF(ISNUMBER(AE17),AE17*Parámetros!$B$9,0)+IF(ISNUMBER(AF17),AF17*Parámetros!$B$10,0)+IF(ISNUMBER(AG17),AG17*Parámetros!$B$11,0))/(IF(ISNUMBER(X17),Parámetros!$B$2,0)+IF(ISNUMBER(Y17),Parámetros!$B$3,0)+IF(ISNUMBER(Z17),Parámetros!$B$4,0)+IF(ISNUMBER(AA17),Parámetros!$B$5,0)+IF(ISNUMBER(AB17),Parámetros!$B$6,0)+IF(ISNUMBER(AC17),Parámetros!$B$7,0)+IF(ISNUMBER(AD17),Parámetros!$B$8,0)+IF(ISNUMBER(AE17),Parámetros!$B$9,0)+IF(ISNUMBER(AF17),Parámetros!$B$10,0)+IF(ISNUMBER(AG17),Parámetros!$B$11,0))) -> 74.909502 | AJ17: =IF(AND(ISNUMBER(Y17),N(Y17)<60),69.9,IF(OR(AND(ISNUMBER(AE17),N(AE17)<80),AND(ISNUMBER(AC17),N(AC17)<50,N(O17)>=2)),84.9,100)) -> 100 | AK17: =IF(AI17="","",MIN(AI17,AJ17)) -> 74.909502 | AL17: =IF($C17="","",IF(AK17="","Gris — menos de 3 fuentes",IF(AND(AK17<Parámetros!$B$14,N17<>"",N(N17)<Parámetros!$B$15,N(Y17)>=60),"Gris — repetir observación",IF(AK17>=Parámetros!$B$13,"Verde",IF(AK17>=Parámetros!$B$14,"Amarillo","Rojo"))))) -> Amarillo | AM17: =IF($C17="","",IF(AND(ISNUMBER(Y17),N(Y17)<60),"Ejecución < 60 %: rojo automático",IF(AND(ISNUMBER(AE17),N(AE17)<80),"PIAR < 80 %: máximo amarillo",IF(AND(ISNUMBER(AC17),N(AC17)<50,N(O17)>=2),"Observación < 50: máximo amarillo",IF(AND(N17<>"",N(N17)<Parámetros!$B$15),"κ < 0,60: observación descartada, repetir","")))))
